Workbook

Sheet Risk Narrative
A1: RISK NARRATIVE — QUALITATIVE ASSESSMENT
A2: Complete this tab BEFORE rating. The four assessment dropdowns are read by the referral checks on the D&O Worksheet, and are cross-checked against the modifiers you select there. Write 'None identified' rather than leaving a box blank.
A4: 1. COMPANY OVERVIEW
B5: Business description — what the company actually does, key segments, geographic footprint
B6: Operates three container and bulk terminals in Singapore and Malaysia, with a contract logistics arm (warehousing, freight forwarding) across Indonesia and Vietnam. Terminals contribute about 62% of revenue and the large majority of EBITDA; logistics is lower margin and more competitive. Roughly 55% of assets sit outside Singapore. Listed on the Mainboard since 2011; founder family retains 38%.
B11: Year of establishment | C11: 1994
B12: Exchange, board and year of listing | C12: SGX Mainboard, 2011
B13: Listing status | C13: SGX Mainboard listed | D13: A company listed under 24 months carries prospectus liability — check Q16 agrees.
B14: Market capitalisation (S$m) | C14: ='D&O Worksheet'!$C$13 -> 680 | D14: Pulled from Q1 so the two tabs cannot disagree.
B15: Approximate number of employees | C15: 2100
A16: 2. RISK AND ADVERSE INFORMATION
B17: Negative news, last 3 to 5 years — media, analyst notes, short-seller reports, NGO or union action
B18: Q1 2026: profit warning following loss of a major Indonesian terminal contract; share price fell 9% in one session. Business press coverage questioned concentration risk. No short-seller reports identified. Sources: SGXNet announcements, Business Times, Reuters, Google News, checked 4 Aug 2026.
B22: Regulatory actions, investigations or fines — MAS, ACRA, CAD, CPIB, SGX RegCo, and any overseas regulator
B23: One SGX unusual price movement query (Feb 2026), answered same day. No fines, no enforcement action, no ongoing investigation in Singapore or in any operating jurisdiction. Indonesian customs dispute (2023) settled without penalty.
B27: Class actions, securities litigation, shareholder or minority-oppression disputes
B28: None identified. No class action, derivative action or Section 216 minority-oppression application. Two commercial contract disputes in the ordinary course, both below S$2m and unrelated to directors' conduct.
B32: Litigation exposure level | C32: Low | D32: Low / Moderate / High. Read by the referral checks. High refers, and must be matched by a debit on modifier 4.
A33: 3. FINANCIAL ANALYSIS
B34: Figures in S$m | C34: FY2025 | D34: FY2024 | E34: FY2023 | F34: Most recent year first
B35: Total assets | C35: 690 | D35: 664 | E35: 651
B36: Total liabilities | C36: 372 | D36: 359 | E36: 359
B37: Revenue | C37: 412 | D37: 388 | E37: 401
B38: Net profit / (loss) | C38: 21 | D38: 26 | E38: 31
B39: Shareholders' equity (assets less liabilities) | C39: =IFERROR(C35-C36,"") -> 318 | D39: =IFERROR(D35-D36,"") -> 305 | E39: =IFERROR(E35-E36,"") -> 292
B40: Liabilities / assets | C40: =IFERROR(C36/C35,"") -> 0.53913043 | D40: =IFERROR(D36/D35,"") -> 0.54066265 | E40: =IFERROR(E36/E35,"") -> 0.55145929
B41: Net margin | C41: =IFERROR(C38/C37,"") -> 0.050970874 | D41: =IFERROR(D38/D37,"") -> 0.067010309 | E41: =IFERROR(E38/E37,"") -> 0.077306733
B43: Trend commentary — direction of revenue, margin, leverage and cash across the three years
B44: Revenue broadly flat (S$401m to S$412m) but net profit down a third over three years, from S$31m to S$21m; net margin has compressed from 7.7% to 5.1% on terminal fee pressure and higher fuel and labour costs. Liabilities/assets has risen from 0.55 to 0.54 on a larger balance sheet, with borrowings up S$29m to fund the Vietnam warehouse. Operating cash flow remains positive and comfortably covers interest.
B48: Red flags — margin compression, leverage, liquidity, covenants, going-concern or audit emphasis language
B49: Three consecutive years of declining profit is the main concern, together with customer concentration in Indonesia. Leverage is moderate and interest cover adequate. No covenant breach, no going-concern emphasis, unqualified audit opinion, auditor unchanged. Liquidity is satisfactory.
B53: Overall financial strength | C53: Adequate | D53: Strong / Adequate / Weak / Serious concern. Weak or worse refers, and must be matched by a debit on modifier 1.
A54: 4. CORPORATE GOVERNANCE AND MANAGEMENT
B55: Role | C55: Name | D55: Years in role | E55: Capital markets experience | F55: Finance or accounting experience | G55: Legal or regulatory experience | H55: Relevant background and credentials
B56: Chairman | C56: Tan Wei Ming | D56: 14 | E56: Yes | F56: No | G56: No | H56: Founder's son. Career in port operations; no prior listed directorship outside the group.
B57: Chief Executive Officer | C57: Sarah Lim | D57: 6 | E57: Yes | F57: Yes | G57: No | H57: Ex-CFO of a listed regional logistics group; led two rights issues.
B58: Chief Financial Officer | C58: Rajesh Kumar | D58: 4 | E58: Yes | F58: Yes | G58: No | H58: CA (Singapore), ex-Big Four audit partner. No adverse findings.
B59: Audit Committee Chair | C59: Grace Ong | D59: 5 | E59: Yes | F59: Yes | G59: No | H59: FCCA, chairs the AC of one other Mainboard issuer.
B60: Lead Independent Director | C60: David Choo | D60: 9 | E60: Yes | F60: No | G60: Yes | H60: Senior counsel, corporate and regulatory practice.
B61: Company Secretary | C61: Michelle Ng | D61: 7 | E61: No | F61: No | G61: Yes | H61: Chartered secretary, 20 years in listed-company compliance.
...

Sheet D&O Worksheet
A1: D&O UNDERWRITING WORKSHEET — SGX-LISTED COMPANY
A2: Fill in the YELLOW cells only; everything grey is calculated. Currency SGD. Complete the Risk Narrative tab FIRST. The entries shown are a worked example for a fictional company — overwrite them.
A4: IDENTIFICATION
B5: Insured (listed entity) | C5: Marina Logistics Holdings Ltd
B6: SGX code and board | C6: M42 / Mainboard
B7: Sector | C7: Marine ports and logistics
B8: Broker and submission date | C8: Example Broking / 4 Aug 2026
A10: PART 1 — THE RISK (20 questions)
B11: Question | C11: Answer | D11: Feeds | E11: Why it matters / how to answer
A12: A. Size and market exposure
B13: 1. Market capitalisation (S$m) | C13: 680 | D13: Base cost | E13: THE EXPOSURE BASE — it caps the plausible size of a securities claim. Closing market cap at the most recent practicable date.
B14: 2. Free float (%) | C14: 0.42 | D14: Mod 3 | E14: A thin float means fewer aggrieved outside holders but sharper price moves and more minority-oppression risk.
B15: 3. Share price movement, last 12 months (%) | C15: -0.18 | D15: Mod 3 | E15: The single best predictor of a securities claim. A fall shortly after upbeat guidance is the classic fact pattern.
B16: 4. Assets or revenue outside Singapore (%) | C16: 0.55 | D16: Mod 4 | E16: An SGX listing with operations elsewhere makes investigation and asset recovery harder. Above 75% refers and suggests a territorial limitation.
A17: B. Financial condition
B18: 5. Net gearing (net debt / equity) | C18: 0.51 | D18: Mod 1 | E18: Above 2.00x is a material debit; above 3.00x refers. Insolvency is the commonest route to a D&O claim in this region.
B19: 6. Profitable in each of the last three financial years? | C19: All three | D19: Mod 1 | E19: Three clean years earns a credit. 'None' means a loss-making issuer — refers, and suggests an insolvency exclusion.
B20: 7. Profit warning, restatement or material adverse announcement in last 12 months? | C20: Yes | D20: Mod 1 / 3 | E20: A restatement is the strongest accounting red flag there is. A Yes suggests a specific matter exclusion.
A21: C. Governance and audit
B22: 8. Independent directors (% of board) | C22: 0.5 | D22: Mod 2 | E22: The SGX Code expects a majority where the chairman is not independent. Below one third, debit hard.
B23: 9. Largest shareholder holding (%) | C23: 0.38 | D23: Mod 2 | E23: Drives interested-person transactions and minority-oppression exposure. Above 15% suggests a major shareholder exclusion; above 30%, an IPT exclusion.
B24: 10. Audit opinion, most recent | C24: Unqualified | D24: Mod 2 | E24: Anything other than unqualified refers.
B25: 11. Change of external auditor in the last 3 years? | C25: No | D25: Mod 2 | E25: Ask WHY. An auditor who resigns mid-engagement is telling you something the accounts are not.
B26: 12. CEO or CFO change in the last 24 months? | C26: No | D26: Mod 2 | E26: An unexplained CFO departure is a recurring precursor to restatement. Get the reason in writing.
A27: D. Regulatory and capital markets
B28: 13. SGX queries received in the last 24 months (number) | C28: 1 | D28: Mod 4 | E28: Count unusual price movement and trade-with-caution queries. Three or more refers.
B29: 14. Watch-list, trading suspension or regulatory investigation? | C29: No | D29: Mod 4 | E29: Covers the SGX watch-list, non-routine suspensions, and any MAS / CAD / ACRA / SGX RegCo matter.
B30: 15. US securities exposure | C30: None | D30: Mod 4 | E30: The largest single driver of D&O severity worldwide. Anything other than None refers and suggests a US securities exclusion.
B31: 16. IPO, RTO or capital raising in the last 24 months? | C31: Placement or rights issue | D31: Mod 4 | E31: An offering document creates prospectus liability. An IPO or RTO refers — consider a public offering exclusion or a separate POSI policy.
A32: E. Claims and insurance history
B33: 17. D&O claims or notifications, last 5 years (number) | C33: 0 | D33: Mod 5 | E33: Any claim at all refers. Ask for the full loss run, not the broker's summary.
B34: 18. Known circumstance disclosed but not yet notified? | C34: No | D34: Mod 5 | E34: A Yes normally means we do not write it until it has been notified to the expiring insurer.
B35: 19. Has any insurer declined, cancelled or non-renewed D&O cover? | C35: No | D35: Mod 5 | E35: Rarely asked, highly informative. Another underwriter has already priced this risk and walked away — find out why.
A36: F. Expiring programme
B37: 20. Expiring premium for the SAME limit and the SAME share (S$) | C37: 55000 | D37: Benchmark | E37: Must be like-for-like. If we wrote 50% last year and 100% this year, gross the expiring figure up first, or the rate change is meaningless. Enter 0 for new business.
A39: PART 2 — THE STRUCTURE
B40: Item | C40: Your selection | D40: Factor | E40: Notes
B41: Base expected loss cost (S$) | C41: =IFERROR(INDEX(Factors!$A$4:$A$12,MATCH(C13,Factors!$B$4:$B$12,1)),"enter Q1") -> 500 to below 1,000 | D41: =IFERROR(INDEX(Factors!$D$4:$D$12,MATCH(C13,Factors!$B$4:$B$12,1)),"enter Q1") -> 25000 | E41: Table A, driven by Q1. This is a LOSS COST, not a premium.
B42: Limit purchased | C42: S$10m | D42: =IFERROR(INDEX(Factors!$B$16:$B$22,MATCH(C42,Factors!$A$16:$A$22,0)),"select") -> 1 | E42: Table B. Increased limit factor, relative to S$10m = 1.00.
B43: Limit in S$m (used by sublimits and referral checks) | D43: =IFERROR(INDEX(Factors!$C$16:$C$22,MATCH(C42,Factors!$A$16:$A$22,0)),0) -> 10 | E43: Read automatically from Table B — nothing to type.
...

Sheet Factors
A1: FACTOR TABLES — do not change without sign-off from the Head of Financial Lines
A3: Market cap band (S$m) | B3: Lower bound (S$m) | C3: Upper bound (S$m) | D3: TABLE A — loss cost (S$)
A4: Below 50 | B4: 0 | C4: 50 | D4: 8000
A5: 50 to below 100 | B5: 50 | C5: 100 | D5: 10500
A6: 100 to below 250 | B6: 100 | C6: 250 | D6: 14000
A7: 250 to below 500 | B7: 250 | C7: 500 | D7: 18500
A8: 500 to below 1,000 | B8: 500 | C8: 1000 | D8: 25000
A9: 1,000 to below 2,500 | B9: 1000 | C9: 2500 | D9: 34000
A10: 2,500 to below 5,000 | B10: 2500 | C10: 5000 | D10: 46000
A11: 5,000 to below 10,000 | B11: 5000 | C11: 10000 | D11: 62000
A12: 10,000 and above | B12: 10000 | C12: 999999 | D12: 82000
A13: Lookup uses the lower bound only; the upper bound column is shown for reading. Basis: S$10m limit, SGD 250k retention, Hazard Class 2, 12 months.
A15: TABLE B — limit | B15: Factor | C15: Limit (S$m) | D15: Comment
A16: S$5m | B16: 0.7 | C16: 5
A17: S$10m | B17: 1 | C17: 10
A18: S$15m | B18: 1.22 | C18: 15
A19: S$20m | B19: 1.4 | C19: 20
A20: S$25m | B20: 1.55 | C20: 25
A21: S$30m | B21: 1.68 | C21: 30
A22: S$50m | B22: 2.05 | C22: 50
A23: Relative to S$10m = 1.00. Column C is read by the worksheet for sublimits and referral checks — keep it aligned with column A.
A25: TABLE C — retention | B25: Retention (S$) | C25: Factor | D25: Comment
A26: SGD 100k | B26: 100000 | C26: 1.15 | D26: Low for a listed company
A27: SGD 250k | B27: 250000 | C27: 1 | D27: Benchmark for an SGX mid-cap
A28: SGD 500k | B28: 500000 | C28: 0.9 | D28: Suits above roughly S$1bn
A29: SGD 1m | B29: 1000000 | C29: 0.8 | D29: Large cap
A30: SGD 2.5m | B30: 2500000 | C30: 0.68 | D30: Large cap only — refer
A33: TABLE D — hazard class | B33: Typical SGX sectors | C33: Factor | D33: Comment
A34: Class 1 | B34: REITs, business trusts, utilities, regulated infrastructure | C34: 0.85 | D34: Stable regulated cash flows
A35: Class 2 | B35: Industrials, consumer staples, transport and logistics, telcos | C35: 1 | D35: Benchmark class
A36: Class 3 | B36: Property developers, construction, agri-commodities, healthcare, hospitality | C36: 1.2 | D36: Cyclical, estimate-heavy accounting
A37: Class 4 | B37: Banks and financial services, offshore and marine, oil and gas, mining, technology | C37: 1.45 | D37: Regulatory intensity, volatile earnings
A38: Class 5 | B38: Pre-revenue biotech, digital assets, Catalist shells, recent RTO or SPAC, distressed | C38: 1.75 | D38: Always refer
A41: TABLE E — parameters | C41: Value | D41: Comment
A42: Minimum premium (S$) | C42: 7500 | D42: Applies to our share
A43: Composite modifier floor | C43: 0.5 | D43: Applied in Part 3
A44: Composite modifier cap | C44: 3.5 | D44: Applied in Part 3
